[2023-09-09 19:00:35,893] {taskinstance.py:1179} INFO - Dependencies all met for <TaskInstance: data_cleaning_dag.data_cleaning scheduled__2023-09-09T18:59:35.036652+00:00 [queued]>
[2023-09-09 19:00:35,897] {taskinstance.py:1179} INFO - Dependencies all met for <TaskInstance: data_cleaning_dag.data_cleaning scheduled__2023-09-09T18:59:35.036652+00:00 [queued]>
[2023-09-09 19:00:35,898] {taskinstance.py:1376} INFO - 
--------------------------------------------------------------------------------
[2023-09-09 19:00:35,898] {taskinstance.py:1377} INFO - Starting attempt 1 of 1
[2023-09-09 19:00:35,898] {taskinstance.py:1378} INFO - 
--------------------------------------------------------------------------------
[2023-09-09 19:00:35,906] {taskinstance.py:1397} INFO - Executing <Task(PythonOperator): data_cleaning> on 2023-09-09 18:59:35.036652+00:00
[2023-09-09 19:00:35,913] {standard_task_runner.py:52} INFO - Started process 208 to run task
[2023-09-09 19:00:35,916] {standard_task_runner.py:79} INFO - Running: ['***', 'tasks', 'run', 'data_cleaning_dag', 'data_cleaning', 'scheduled__2023-09-09T18:59:35.036652+00:00', '--job-id', '6', '--raw', '--subdir', 'DAGS_FOLDER/data_cleaning_dag/data_cleaning.py', '--cfg-path', '/tmp/tmpzs1fb6se', '--error-file', '/tmp/tmpgyuu3v0v']
[2023-09-09 19:00:35,919] {standard_task_runner.py:80} INFO - Job 6: Subtask data_cleaning
[2023-09-09 19:00:35,965] {task_command.py:371} INFO - Running <TaskInstance: data_cleaning_dag.data_cleaning scheduled__2023-09-09T18:59:35.036652+00:00 [running]> on host 0f153183a9bf
[2023-09-09 19:00:36,008] {taskinstance.py:1591} INFO - Exporting the following env vars:
AIRFLOW_CTX_DAG_OWNER=***
AIRFLOW_CTX_DAG_ID=data_cleaning_dag
AIRFLOW_CTX_TASK_ID=data_cleaning
AIRFLOW_CTX_EXECUTION_DATE=2023-09-09T18:59:35.036652+00:00
AIRFLOW_CTX_TRY_NUMBER=1
AIRFLOW_CTX_DAG_RUN_ID=scheduled__2023-09-09T18:59:35.036652+00:00
[2023-09-09 19:00:36,010] {taskinstance.py:1909} ERROR - Task failed with exception
Traceback (most recent call last):
  File "/home/airflow/.local/lib/python3.7/site-packages/airflow/operators/python.py", line 171, in execute
    return_value = self.execute_callable()
  File "/home/airflow/.local/lib/python3.7/site-packages/airflow/operators/python.py", line 189, in execute_callable
    return self.python_callable(*self.op_args, **self.op_kwargs)
  File "/opt/airflow/dags/data_cleaning_dag/data_cleaning.py", line 13, in data_cleaning
    hotel_data = pd.read_csv("raw_data/hotel_bookings.csv") #Importing our raw data.
  File "/home/airflow/.local/lib/python3.7/site-packages/pandas/util/_decorators.py", line 311, in wrapper
    return func(*args, **kwargs)
  File "/home/airflow/.local/lib/python3.7/site-packages/pandas/io/parsers/readers.py", line 586, in read_csv
    return _read(filepath_or_buffer, kwds)
  File "/home/airflow/.local/lib/python3.7/site-packages/pandas/io/parsers/readers.py", line 482, in _read
    parser = TextFileReader(filepath_or_buffer, **kwds)
  File "/home/airflow/.local/lib/python3.7/site-packages/pandas/io/parsers/readers.py", line 811, in __init__
    self._engine = self._make_engine(self.engine)
  File "/home/airflow/.local/lib/python3.7/site-packages/pandas/io/parsers/readers.py", line 1040, in _make_engine
    return mapping[engine](self.f, **self.options)  # type: ignore[call-arg]
  File "/home/airflow/.local/lib/python3.7/site-packages/pandas/io/parsers/c_parser_wrapper.py", line 51, in __init__
    self._open_handles(src, kwds)
  File "/home/airflow/.local/lib/python3.7/site-packages/pandas/io/parsers/base_parser.py", line 229, in _open_handles
    errors=kwds.get("encoding_errors", "strict"),
  File "/home/airflow/.local/lib/python3.7/site-packages/pandas/io/common.py", line 707, in get_handle
    newline="",
FileNotFoundError: [Errno 2] No such file or directory: 'raw_data/hotel_bookings.csv'
[2023-09-09 19:00:36,017] {taskinstance.py:1420} INFO - Marking task as FAILED. dag_id=data_cleaning_dag, task_id=data_cleaning, execution_date=20230909T185935, start_date=20230909T190035, end_date=20230909T190036
[2023-09-09 19:00:36,022] {standard_task_runner.py:97} ERROR - Failed to execute job 6 for task data_cleaning ([Errno 2] No such file or directory: 'raw_data/hotel_bookings.csv'; 208)
[2023-09-09 19:00:36,055] {local_task_job.py:156} INFO - Task exited with return code 1
[2023-09-09 19:00:36,081] {local_task_job.py:273} INFO - 0 downstream tasks scheduled from follow-on schedule check
